Workbook

Sheet W
B1: Wafer Yield Map
B2: Lot | C2: 93449 | D2: Wafer # | E2: 07 | G2: Fab | H2: AFSW
B3: Test condition | D3: reverse BV at 1mA for surface diode Unit (V)
B4: Test Date | C4: =TODAY() | D4: Test Engineer
C6: 41.670723 | D6: 22.139771 | E6: 55.075523 | F6: 57.911884 | G6: 59.23312 | H6: -0.32125458 | Q6: Die 1 | R6: Die 2 | S6: Die 3 | T6: Die 4 | U6: Die 5 | V6: Die 6
C7: Die 1 | D7: Die 2 | E7: Die 3 | F7: Die 4 | G7: Die 5 | H7: Die 6
C8: 61.654259 | D8: 60.450287 | E8: 60.639065 | F8: 60.664089 | G8: 59.839996 | H8: 24.78203
B9: 61.865479 | C9: 58.984985 | D9: 59.736626 | E9: 57.755669 | F9: 59.475842 | G9: 56.505421 | H9: 48.43774 | I9: 45.566956 | P9: Die 7 | Q9: Die 8 | R9: Die 9 | S9: Die 10 | T9: Die 11 | U9: Die 12 | V9: Die 13 | W9: Die 14
B10: Die 7 | C10: Die 8 | D10: Die 9 | E10: Die 10 | F10: Die 11 | G10: Die 12 | H10: Die 13 | I10: Die 14
B11: 67.289635 | C11: 65.860611 | D11: 61.498333 | E11: 61.475887 | F11: 64.924675 | G11: 61.569454 | H11: 61.895237 | I11: 62.13781
A12: -4.079792 | B12: 59.355423 | C12: 59.7374 | D12: 61.416576 | E12: 60.231171 | F12: 59.668316 | G12: 59.389927 | H12: 59.495956 | I12: 60.598442 | J12: 60.506428 | O12: Die 15 | P12: Die 16 | Q12: Die 17 | R12: Die 18 | S12: Die 19 | T12: Die 20 | U12: Die 21 | V12: Die 22 | W12: Die 23 | X12: Die 24
A13: Die 15 | B13: Die 16 | C13: Die 17 | D13: Die 18 | E13: Die 19 | F13: Die 20 | G13: Die 21 | H13: Die 22 | I13: Die 23 | J13: Die 24
A14: 62.903076 | B14: 63.723938 | C14: 66.43734 | D14: 72.015823 | E14: 69.47213 | F14: 64.875748 | G14: 68.217369 | H14: 62.599426 | I14: 61.390488 | J14: 62.521683
A15: 61.332939 | B15: 65.733055 | C15: 64.023254 | D15: 60.28717 | E15: 58.966236 | F15: 60.281445 | G15: 61.28413 | H15: 59.890751 | I15: 59.990551 | J15: 61.656128 | O15: Die 25 | P15: Die 26 | Q15: Die 27 | R15: Die 28 | S15: Die 29 | T15: Die 30 | U15: Die 31 | V15: Die 32 | W15: Die 33 | X15: Die 34
A16: Die 25 | B16: Die 26 | C16: Die 27 | D16: Die 28 | E16: Die 29 | F16: Die 30 | G16: Die 31 | H16: Die 32 | I16: Die 33 | J16: Die 34
A17: 73.105904 | B17: 76.774582 | C17: 67.621643 | D17: 74.173561 | E17: 71.755714 | F17: 68.096199 | G17: 63.543205 | H17: 69.97036 | I17: 65.383484 | J17: 82.732162
A18: 59.110596 | B18: 62.694805 | C18: 62.916813 | D18: 64.541039 | E18: 61.500179 | F18: 62.293606 | G18: 61.428616 | H18: 59.626915 | I18: 60.024017 | J18: 59.629086 | O18: Die 35 | P18: Die 36 | Q18: Die 37 | R18: Die 38 | S18: Die 39 | T18: Die 40 | U18: Die 41 | V18: Die 42 | W18: Die 43 | X18: Die 44
A19: Die 35 | B19: Die 36 | C19: Die 37 | D19: Die 38 | E19: Die 39 | F19: Die 40 | G19: Die 41 | H19: Die 42 | I19: Die 43 | J19: Die 44
A20: 85.909569 | B20: 79.05558 | C20: 64.174767 | D20: 83.422432 | E20: 75.452919 | F20: 75.119965 | G20: 66.858238 | H20: 63.917336 | I20: 68.827606 | J20: 70.79052
A21: 60.548077 | B21: 63.706177 | C21: 65.850578 | D21: 59.862099 | E21: 60.817966 | F21: 60.334869 | G21: 59.978474 | H21: 64.852005 | I21: 61.291428 | J21: 60.608681 | O21: Die 45 | P21: Die 46 | Q21: Die 47 | R21: Die 48 | S21: Die 49 | T21: Die 50 | U21: Die 51 | V21: Die 52 | W21: Die 53 | X21: Die 54
A22: Die 45 | B22: Die 46 | C22: Die 47 | D22: Die 48 | E22: Die 49 | F22: Die 50 | G22: Die 51 | H22: Die 52 | I22: Die 53 | J22: Die 54
A23: 89.239258 | B23: 89.979294 | C23: 82.917274 | D23: 78.775131 | E23: 80.322845 | F23: 73.670189 | G23: 81.546837 | H23: 77.596291 | I23: 84.805237 | J23: 72.093727
A24: 43.797951 | B24: 57.855946 | C24: 66.835167 | D24: 60.941238 | E24: 61.286186 | F24: 61.70192 | G24: 60.700344 | H24: 60.870724 | I24: 61.784924 | J24: 63.379856 | O24: Die 55 | P24: Die 56 | Q24: Die 57 | R24: Die 58 | S24: Die 59 | T24: Die 60 | U24: Die 61 | V24: Die 62 | W24: Die 63 | X24: Die 64
A25: Die 55 | B25: Die 56 | C25: Die 57 | D25: Die 58 | E25: Die 59 | F25: Die 60 | G25: Die 61 | H25: Die 62 | I25: Die 63 | J25: Die 64
A26: 85.909569 | B26: 79.05558 | C26: 64.174767 | D26: 83.422432 | E26: 75.452919 | F26: 75.119965 | G26: 66.858238 | H26: 63.917336 | I26: 68.827606 | J26: 70.79052
A27: 63.305023 | B27: 67.224922 | C27: 60.537586 | D27: 66.259468 | E27: 66.316406 | F27: 65.676048 | G27: 63.072533 | H27: 63.379696 | I27: 61.928982 | J27: 62.09914 | O27: Die 65 | P27: Die 66 | Q27: Die 67 | R27: Die 68 | S27: Die 69 | T27: Die 70 | U27: Die 71 | V27: Die 72 | W27: Die 73 | X27: Die 74
A28: Die 65 | B28: Die 66 | C28: Die 67 | D28: Die 68 | E28: Die 69 | F28: Die 70 | G28: Die 71 | H28: Die 72 | I28: Die 73 | J28: Die 74
A29: 73.105904 | B29: 76.774582 | C29: 67.621643 | D29: 74.173561 | E29: 71.755714 | F29: 68.096199 | G29: 63.543205 | H29: 69.97036 | I29: 65.383484 | J29: 82.732162
B30: 43.834602 | C30: 37.122166 | D30: 60.243595 | E30: 61.620853 | F30: 62.23922 | G30: 66.676422 | H30: 66.186432 | I30: 67.38356 | P30: Die 75 | Q30: Die 76 | R30: Die 77 | S30: Die 78 | T30: Die 79 | U30: Die 80 | V30: Die 81 | W30: Die 82
B31: Die 75 | C31: Die 76 | D31: Die 77 | E31: Die 78 | F31: Die 79 | G31: Die 80 | H31: Die 81 | I31: Die 82
B32: 62.903076 | C32: 63.723938 | D32: 66.43734 | E32: 72.015823 | F32: 69.47213 | G32: 64.875748 | H32: 68.217369 | I32: 62.599426
C33: 34.371841 | D33: 61.625195 | E33: 65.812843 | F33: 29.460978 | G33: 41.09481 | H33: 11.870625 | Q33: Die 83 | R33: Die 84 | S33: Die 85 | T33: Die 86 | U33: Die 87 | V33: Die 88
C34: Die 83 | D34: Die 84 | E34: Die 85 | F34: Die 86 | G34: Die 87 | H34: Die 88
C35: 61.390488 | D35: 62.521683 | E35: 67.289635 | F35: 65.860611 | G35: 61.498333 | H35: 61.475887
D36: Flat
R37: Flat
A38: ="Yield (> " & $B$48 & "V):" | C38: Data Deviation
A39: Front | B39: =ROUNDUP(H140,2)&"%" | C39: =ROUNDUP(STDEVA(F52:F139),1) | F39: Front Side Testing
A40: Back | B40: =ROUNDUP(I140,2)&"%" | C40: =ROUNDUP(STDEVA(G52:G139),1) | F40: Back Side Testing | S40: ="Bidirectional device >"& $B$48 &"V both sides" | T40: =COUNTIF($N$52:$N$139,"BD")
A41: Total | B41: =ROUNDUP(J140,2)&"%" | S41: ="Single Directional Device >"& ROUNDDOWN($B$48/2,0) &"V one side" | T41: =COUNTIF($N$52:$N$139,"UD")
...

Sheet E1E2-E2E1
A1: =A3*3 | B1: ideal *3
A2: =A3*2 | B2: ideal *2
A3: =1.6*1.1 | B3: ideal +10%
B6: E1E2 | C6: =W!$K$52 | D6: =W!$K$53 | E6: =W!$K$54 | F6: =W!$K$55 | G6: =W!$K$56 | H6: =W!$K$57
C7: Die 1 | D7: Die 2 | E7: Die 3 | F7: Die 4 | G7: Die 5 | H7: Die 6
B8: E2E1 | C8: =W!$O$52 | D8: =W!$O$53 | E8: =W!$O$54 | F8: =W!$O$55 | G8: =W!$O$56 | H8: =W!$O$57
B9: =W!$K$58 | C9: =W!$K$59 | D9: =W!$K$60 | E9: =W!$K$61 | F9: =W!$K$62 | G9: =W!$K$63 | H9: =W!$K$64 | I9: =W!$K$65
B10: Die 7 | C10: Die 8 | D10: Die 9 | E10: Die 10 | F10: Die 11 | G10: Die 12 | H10: Die 13 | I10: Die 14
B11: =W!$O$58 | C11: =W!$O$59 | D11: =W!$O$60 | E11: =W!$O$61 | F11: =W!$O$62 | G11: =W!$O$63 | H11: =W!$O$64 | I11: =W!$O$65
A12: =W!$K$66 | B12: =W!$K$67 | C12: =W!$K$68 | D12: =W!$K$69 | E12: =W!$K$70 | F12: =W!$K$71 | G12: =W!$K$72 | H12: =W!$K$73 | I12: =W!$K$74 | J12: =W!$K$75
A13: Die 15 | B13: Die 16 | C13: Die 17 | D13: Die 18 | E13: Die 19 | F13: Die 20 | G13: Die 21 | H13: Die 22 | I13: Die 23 | J13: Die 24
A14: =W!$O$66 | B14: =W!$O$67 | C14: =W!$O$68 | D14: =W!$O$69 | E14: =W!$O$70 | F14: =W!$O$71 | G14: =W!$O$72 | H14: =W!$O$73 | I14: =W!$O$74 | J14: =W!$O$75
A15: =W!$K$76 | B15: =W!$K$77 | C15: =W!$K$78 | D15: =W!$K$79 | E15: =W!$K$80 | F15: =W!$K$81 | G15: =W!$K$82 | H15: =W!$K$83 | I15: =W!$K$84 | J15: =W!$K$85
A16: Die 25 | B16: Die 26 | C16: Die 27 | D16: Die 28 | E16: Die 29 | F16: Die 30 | G16: Die 31 | H16: Die 32 | I16: Die 33 | J16: Die 34
A17: =W!$O$76 | B17: =W!$O$77 | C17: =W!$O$78 | D17: =W!$O$79 | E17: =W!$O$80 | F17: =W!$O$81 | G17: =W!$O$82 | H17: =W!$O$83 | I17: =W!$O$84 | J17: =W!$O$85
A18: =W!$K$86 | B18: =W!$K$87 | C18: =W!$K$88 | D18: =W!$K$89 | E18: =W!$K$90 | F18: =W!$K$91 | G18: =W!$K$92 | H18: =W!$K$93 | I18: =W!$K$94 | J18: =W!$K$95
A19: Die 35 | B19: Die 36 | C19: Die 37 | D19: Die 38 | E19: Die 39 | F19: Die 40 | G19: Die 41 | H19: Die 42 | I19: Die 43 | J19: Die 44
A20: =W!$O$86 | B20: =W!$O$87 | C20: =W!$O$88 | D20: =W!$O$89 | E20: =W!$O$90 | F20: =W!$O$91 | G20: =W!$O$92 | H20: =W!$O$93 | I20: =W!$O$94 | J20: =W!$O$95
A21: =W!$K$96 | B21: =W!$K$97 | C21: =W!$K$98 | D21: =W!$K$99 | E21: =W!$K$100 | F21: =W!$K$101 | G21: =W!$K$102 | H21: =W!$K$103 | I21: =W!$K$104 | J21: =W!$K$105
A22: Die 45 | B22: Die 46 | C22: Die 47 | D22: Die 48 | E22: Die 49 | F22: Die 50 | G22: Die 51 | H22: Die 52 | I22: Die 53 | J22: Die 54
A23: =W!$O$96 | B23: =W!$O$97 | C23: =W!$O$98 | D23: =W!$O$99 | E23: =W!$O$100 | F23: =W!$O$101 | G23: =W!$O$102 | H23: =W!$O$103 | I23: =W!$O$104 | J23: =W!$O$105
A24: =W!$K$106 | B24: =W!$K$107 | C24: =W!$K$108 | D24: =W!$K$109 | E24: =W!$K$110 | F24: =W!$K$111 | G24: =W!$K$112 | H24: =W!$K$113 | I24: =W!$K$114 | J24: =W!$K$115
A25: Die 55 | B25: Die 56 | C25: Die 57 | D25: Die 58 | E25: Die 59 | F25: Die 60 | G25: Die 61 | H25: Die 62 | I25: Die 63 | J25: Die 64
A26: =W!$O$106 | B26: =W!$O$107 | C26: =W!$O$108 | D26: =W!$O$109 | E26: =W!$O$110 | F26: =W!$O$111 | G26: =W!$O$112 | H26: =W!$O$113 | I26: =W!$O$114 | J26: =W!$O$115
A27: =W!$K$116 | B27: =W!$K$117 | C27: =W!$K$118 | D27: =W!$K$119 | E27: =W!$K$120 | F27: =W!$K$121 | G27: =W!$K$122 | H27: =W!$K$123 | I27: =W!$K$124 | J27: =W!$K$125
A28: Die 65 | B28: Die 66 | C28: Die 67 | D28: Die 68 | E28: Die 69 | F28: Die 70 | G28: Die 71 | H28: Die 72 | I28: Die 73 | J28: Die 74
A29: =W!$O$116 | B29: =W!$O$117 | C29: =W!$O$118 | D29: =W!$O$119 | E29: =W!$O$120 | F29: =W!$O$121 | G29: =W!$O$122 | H29: =W!$O$123 | I29: =W!$O$124 | J29: =W!$O$125
B30: =W!$K$126 | C30: =W!$K$127 | D30: =W!$K$128 | E30: =W!$K$129 | F30: =W!$K$130 | G30: =W!$K$131 | H30: =W!$K$132 | I30: =W!$K$133
B31: Die 75 | C31: Die 76 | D31: Die 77 | E31: Die 78 | F31: Die 79 | G31: Die 80 | H31: Die 81 | I31: Die 82
B32: =W!$O$126 | C32: =W!$O$127 | D32: =W!$O$128 | E32: =W!$O$129 | F32: =W!$O$130 | G32: =W!$O$131 | H32: =W!$O$132 | I32: =W!$O$133
C33: =W!$K$134 | D33: =W!$K$135 | E33: =W!$K$136 | F33: =W!$K$137 | G33: =W!$K$138 | H33: =W!$K$139
C34: Die 83 | D34: Die 84 | E34: Die 85 | F34: Die 86 | G34: Die 87 | H34: Die 88
C35: =W!$O$134 | D35: =W!$O$135 | E35: =W!$O$136 | F35: =W!$O$137 | G35: =W!$O$138 | H35: =W!$O$139
D36: Flat
A39: High Value | B39: =IF(OR(W!C43<>"",W!C44<>""),MAX(C6:H6,C8:H8,B9:I9,B11:I11,A12:J12,A14:J14,A15:J15,A17:J17,A18:J18,A20:J20,A21:J21,A23:J23,A24:J24,A26:J26,A27:J27,A29:J29,B30:I30,B32:I32,C33:H33,C35:H35),"")
A40: Low Value | B40: =IF(OR(W!C43<>"",W!C44<>""),MIN(C6:H6,C8:H8,B9:I9,B11:I11,A12:J12,A14:J14,A15:J15,A17:J17,A18:J18,A20:J20,A21:J21,A23:J23,A24:J24,A26:J26,A27:J27,A29:J29,B30:I30,B32:I32,C33:H33,C35:H35),"")
A41: Avg E1E2 | B41: =IF(OR(W!C43<>"",W!C44<>""),W!C43,"")
A42: Avg E2E1 | B42: =IF(OR(W!C43<>"",W!C44<>""),W!C44,"")
A43: E1E2 Dev | B43: =IF(OR(W!C43<>"",W!C44<>""),_xlfn.STDEV.S(C6:H6,B9:I9,A12:J12,A15:J15,A18:J18,A21:J21,A24:J24,A27:J27,B30:I30,C33:H33),"")
A44: E2E1 Dev | B44: =IF(OR(W!C43<>"",W!C44<>""),_xlfn.STDEV.S(C8:H8,B11:I11,A14:J14,A17:J17,A20:J20,A23:J23,A26:J26,A29:J29,B32:I32,C35:H35),"")
...

Sheet txtformat
A1: =_xlfn.CONCAT("WaferID=5L0F6E5-",IF(W!C2<>"",W!C2,"12345"),"_",IF(W!E2<>"",IF(LEN(W!E2)=1,"0"&W!E2,W!E2),"67"))
A2: Part Number=IPAD01210AST
A3: Wafer Size=150 mm
A4: XDIES=11.286 mm
A5: YDIES=11.276 mm
A6: =_xlfn.CONCAT("BinA=",COUNTIF(W!AA52:AA139,"A"))
A7: =IF(W!C2="","",_xlfn.CONCAT("..",W!AA52,W!AA53,W!AA54,W!AA55,W!AA56,W!AA57,".."))
A8: =IF(W!C2="","",_xlfn.CONCAT(".",W!AA58,W!AA59,W!AA60,W!AA61,W!AA62,W!AA63,W!AA64,W!AA65,"."))
A9: =_xlfn.CONCAT(W!AA66,W!AA67,W!AA68,W!AA69,W!AA70,W!AA71,W!AA72,W!AA73,W!AA74,W!AA75)
A10: =_xlfn.CONCAT(W!AA76,W!AA77,W!AA78,W!AA79,W!AA80,W!AA81,W!AA82,W!AA83,W!AA84,W!AA85)
A11: =_xlfn.CONCAT(W!AA86,W!AA87,W!AA88,W!AA89,W!AA90,W!AA91,W!AA92,W!AA93,W!AA94,W!AA95)
A12: =_xlfn.CONCAT(W!AA96,W!AA97,W!AA98,W!AA99,W!AA100,W!AA101,W!AA102,W!AA103,W!AA104,W!AA105)
A13: =_xlfn.CONCAT(W!AA106,W!AA107,W!AA108,W!AA109,W!AA110,W!AA111,W!AA112,W!AA113,W!AA114,W!AA115)
A14: =_xlfn.CONCAT(W!AA116,W!AA117,W!AA118,W!AA119,W!AA120,W!AA121,W!AA122,W!AA123,W!AA124,W!AA125)
A15: =IF(W!C2="","",_xlfn.CONCAT(".",W!AA126,W!AA127,W!AA128,W!AA129,W!AA130,W!AA131,W!AA132,W!AA133,"."))
A16: =IF(W!C2="","",_xlfn.CONCAT("..",W!AA134,W!AA135,W!AA136,W!AA137,W!AA138,W!AA139,".."))
